#VRML_SIM R2023a utf8

EXTERNPROTO "https://raw.githubusercontent.com/cyberbotics/webots/R2023a/projects/appearances/protos/OsbWood.proto"
EXTERNPROTO "https://raw.githubusercontent.com/cyberbotics/webots/R2023a/projects/objects/floors/protos/RectangleArena.proto"
EXTERNPROTO "https://raw.githubusercontent.com/cyberbotics/webots/R2023a/projects/objects/backgrounds/protos/TexturedBackground.proto"
EXTERNPROTO "https://raw.githubusercontent.com/cyberbotics/webots/R2023a/projects/objects/backgrounds/protos/TexturedBackgroundLight.proto"

WorldInfo {
  info [
    "In this example, the robot moves down a slope."
    "The altimeter is used to record the robots height."
  ]
  title "Altimeter"
  basicTimeStep 8
  contactProperties [
    ContactProperties {
      material2 "body"
      coulombFriction [
        0
      ]
      softCFM 0.1
    }
  ]
}
Viewpoint {
  orientation -0.056556363808226935 -0.3323053318431017 0.9414746646306725 5.9255005654949
  position -0.8461797939803826 0.22424370587494358 0.15242197584999298
}
TexturedBackground {
}
TexturedBackgroundLight {
}
RectangleArena {
}
PointLight {
  attenuation 0 0 1
  intensity 0.6
  location 0.6 0 0
}
DEF SLOPE Solid {
  translation 0 0 0.15
  rotation 0 1 0 -0.4
  children [
    Shape {
      appearance OsbWood {
        textureTransform TextureTransform {
          scale 0.5 2
        }
      }
      geometry DEF BOX0 Box {
        size 0.8 0.2 0.02
      }
    }
  ]
  name "green box"
  boundingObject USE BOX0
}
Robot {
  translation -0.09963399866123053 1.709401205331633e-05 0.1188377287886406
  rotation -0.24583003735621956 -1.41655788780624e-06 0.9693129488103587 3.141545578376391
  children [
    Altimeter {
    }
    Transform {
      translation 0 0 0.0415
      children [
        Shape {
          appearance PBRAppearance {
            baseColor 0.0820075 0.364731 0.8
            roughness 1
            metalness 0
          }
          geometry DEF BODY Cylinder {
            height 0.08
            radius 0.045
          }
        }
      ]
    }
    HingeJoint {
      jointParameters HingeJointParameters {
        position 16.720002415869338
        axis 0 1 0
        anchor 0 0 0.025
      }
      device [
        RotationalMotor {
          name "left wheel motor"
          consumptionFactor 70
        }
        PositionSensor {
          name "left wheel sensor"
        }
      ]
      endPoint Solid {
        translation 0 0.04499999999999979 0.025
        rotation -0.6929920009655448 0.6929920536857767 -0.19880669034552143 2.7490969420921876
        children [
          DEF WHEEL Transform {
            rotation 0.577656895078166 0.5771968951617173 -0.5771968951617173 -2.093935
            children [
              Shape {
                appearance PBRAppearance {
                  baseColor 1 0 0
                  roughness 1
                  metalness 0
                }
                geometry Cylinder {
                  height 0.01
                  radius 0.025
                }
              }
            ]
          }
        ]
        name "left wheel"
        boundingObject USE WHEEL
        physics DEF PHYSICS_WHEEL Physics {
          density -1
          mass 0.05
        }
        linearVelocity -5.278952348533036e-06 -2.155747046259324e-13 -2.231905711838066e-06
        angularVelocity 9.429191070071852e-09 -1.0109419551336615e-10 -2.2274743687230358e-08
      }
    }
    DistanceSensor {
      translation 0.042 0.02 0.063
      rotation 0 0 -1 -0.499
      children [
        DEF SENSOR Transform {
          rotation 0.5773502691896258 0.5773502691896258 -0.5773502691896258 -2.093
          children [
            Shape {
              appearance PBRAppearance {
                baseColor 0.97 0.98 0.025
                roughness 1
                metalness 0
              }
              geometry Cylinder {
                height 0.004
                radius 0.008
              }
            }
          ]
        }
      ]
      name "ds0"
      lookupTable [
        0.15 0 0
        0 1024 0
        0.05 1024 0
      ]
    }
    DistanceSensor {
      translation 0.042 -0.02 0.063
      rotation 0 0 -1 -0.499
      children [
        USE SENSOR
      ]
      name "ds1"
      lookupTable [
        0.15 0 0
        0 1024 0
        0.05 1024 0
      ]
    }
    DEF SMILE Transform {
      translation 0.036 0 0.025
      rotation 0.25009693134498434 -0.9353625232302415 -0.25009693134498434 1.637
      children [
        Shape {
          appearance PBRAppearance {
            baseColor 0.7215 0.054 0.52
            roughness 1
            metalness 0
          }
          geometry Cylinder {
            height 0.018
            radius 0.009
            subdivision 3
          }
        }
      ]
    }
    HingeJoint {
      jointParameters HingeJointParameters {
        position 16.7200024053961
        axis 0 1 0
        anchor 0 0 0.025
      }
      device [
        RotationalMotor {
          name "right wheel motor"
          consumptionFactor 70
        }
        PositionSensor {
          name "right wheel sensor"
        }
      ]
      endPoint Solid {
        translation 0 -0.045 0.025
        rotation -0.6929920004244335 0.6929920531446657 -0.19880669411788635 2.749096934834318
        children [
          USE WHEEL
        ]
        boundingObject USE WHEEL
        physics USE PHYSICS_WHEEL
        linearVelocity -5.2769476141900636e-06 -3.1781572382497213e-13 -2.231057101411694e-06
        angularVelocity 9.429164531028338e-09 -1.0106467437107614e-10 -2.2274742842624303e-08
      }
    }
  ]
  name "MyBot"
  contactMaterial "body"
  boundingObject Transform {
    translation 0 0 0.0415
    rotation 0 0 1 -1.570796
    children [
      USE BODY
    ]
  }
  physics Physics {
    density -1
    mass 0.5
  }
  controller ""
}
